Workbook

Sheet kchs_2021_pmt_variables
A1: original_name | B1: Calculated_name_after_Transformation | C1: original_name_after_Transformation | D1: newFIOA_name | E1: In_Merged_name | F1: In_Training_Data
A2: hhid | B2: hhid | C2: hhid | D2: hhid | E2: hhid | F2: =IFERROR(VLOOKUP(D2,FIOA_PMT_Variables_in_Merged!A:C,1,0),"") -> hhid
A3: county | B3: =A3 -> county | C3: county | D3: County | E3: =IFERROR(VLOOKUP(A3,All_Variables_in_Merged!A:C,1,0),IFERROR(VLOOKUP(B3,All_Variables_in_Merged!A:C,1,0),IFERROR(VLOOKUP(D3,All_Variables_in_Merged!A:C,1,0),""))) -> county | F3: =IFERROR(VLOOKUP(D3,FIOA_PMT_Variables_in_Merged!A:C,1,0),"") -> County
A4: total_persons_household | B4: =A4 -> total_persons_household | C4: total_persons_household | D4: household_size | E4: =IFERROR(VLOOKUP(A4,All_Variables_in_Merged!A:C,1,0),IFERROR(VLOOKUP(B4,All_Variables_in_Merged!A:C,1,0),IFERROR(VLOOKUP(D4,All_Variables_in_Merged!A:C,1,0),""))) -> total_persons_household | F4: =IFERROR(VLOOKUP(D4,FIOA_PMT_Variables_in_Merged!A:C,1,0),"") -> household_size
D5: mm_age | E5: =IFERROR(VLOOKUP(A5,All_Variables_in_Merged!A:C,1,0),IFERROR(VLOOKUP(B5,All_Variables_in_Merged!A:C,1,0),IFERROR(VLOOKUP(D5,All_Variables_in_Merged!A:C,1,0),""))) -> mm_age | F5: =IFERROR(VLOOKUP(D5,FIOA_PMT_Variables_in_Merged!A:C,1,0),"") -> mm_age
D6: prop_over65 | E6: =IFERROR(VLOOKUP(A6,All_Variables_in_Merged!A:C,1,0),IFERROR(VLOOKUP(B6,All_Variables_in_Merged!A:C,1,0),IFERROR(VLOOKUP(D6,All_Variables_in_Merged!A:C,1,0),""))) -> prop_over65 | F6: =IFERROR(VLOOKUP(D6,FIOA_PMT_Variables_in_Merged!A:C,1,0),"") -> prop_over65
D7: prop_under5 | E7: =IFERROR(VLOOKUP(A7,All_Variables_in_Merged!A:C,1,0),IFERROR(VLOOKUP(B7,All_Variables_in_Merged!A:C,1,0),IFERROR(VLOOKUP(D7,All_Variables_in_Merged!A:C,1,0),""))) -> prop_under5 | F7: =IFERROR(VLOOKUP(D7,FIOA_PMT_Variables_in_Merged!A:C,1,0),"") -> prop_under5
D8: prop_m1864 | E8: =IFERROR(VLOOKUP(A8,All_Variables_in_Merged!A:C,1,0),IFERROR(VLOOKUP(B8,All_Variables_in_Merged!A:C,1,0),IFERROR(VLOOKUP(D8,All_Variables_in_Merged!A:C,1,0),""))) -> prop_m1864 | F8: =IFERROR(VLOOKUP(D8,FIOA_PMT_Variables_in_Merged!A:C,1,0),"") -> prop_m1864
D9: prop_w1864 | E9: =IFERROR(VLOOKUP(A9,All_Variables_in_Merged!A:C,1,0),IFERROR(VLOOKUP(B9,All_Variables_in_Merged!A:C,1,0),IFERROR(VLOOKUP(D9,All_Variables_in_Merged!A:C,1,0),""))) -> prop_w1864 | F9: =IFERROR(VLOOKUP(D9,FIOA_PMT_Variables_in_Merged!A:C,1,0),"") -> prop_w1864
B10: hhhead_sex | C10: hhhead_sex | D10: hhhead_woman | E10: =IFERROR(VLOOKUP(A10,All_Variables_in_Merged!A:C,1,0),IFERROR(VLOOKUP(B10,All_Variables_in_Merged!A:C,1,0),IFERROR(VLOOKUP(D10,All_Variables_in_Merged!A:C,1,0),""))) -> hhhead_sex | F10: =IFERROR(VLOOKUP(D10,FIOA_PMT_Variables_in_Merged!A:C,1,0),"") -> hhhead_woman
A11: worked_past_week | B11: =A11 -> worked_past_week | C11: worked_past_week | D11: working | E11: =IFERROR(VLOOKUP(A11,All_Variables_in_Merged!A:C,1,0),IFERROR(VLOOKUP(B11,All_Variables_in_Merged!A:C,1,0),IFERROR(VLOOKUP(D11,All_Variables_in_Merged!A:C,1,0),""))) -> worked_past_week | F11: =IFERROR(VLOOKUP(D11,FIOA_PMT_Variables_in_Merged!A:C,1,0),"") -> working
D12: marital_status | E12: =IFERROR(VLOOKUP(A12,All_Variables_in_Merged!A:C,1,0),IFERROR(VLOOKUP(B12,All_Variables_in_Merged!A:C,1,0),IFERROR(VLOOKUP(D12,All_Variables_in_Merged!A:C,1,0),""))) -> marital_status | F12: =IFERROR(VLOOKUP(D12,FIOA_PMT_Variables_in_Merged!A:C,1,0),"") -> marital_status
D13: education_level | E13: =IFERROR(VLOOKUP(A13,All_Variables_in_Merged!A:C,1,0),IFERROR(VLOOKUP(B13,All_Variables_in_Merged!A:C,1,0),IFERROR(VLOOKUP(D13,All_Variables_in_Merged!A:C,1,0),""))) | F13: =IFERROR(VLOOKUP(D13,FIOA_PMT_Variables_in_Merged!A:C,1,0),"")
A14: main_dwelling_type | B14: =A14 -> main_dwelling_type | C14: main_dwelling_type | D14: dwelling | E14: =IFERROR(VLOOKUP(A14,All_Variables_in_Merged!A:C,1,0),IFERROR(VLOOKUP(B14,All_Variables_in_Merged!A:C,1,0),IFERROR(VLOOKUP(D14,All_Variables_in_Merged!A:C,1,0),""))) -> main_dwelling_type | F14: =IFERROR(VLOOKUP(D14,FIOA_PMT_Variables_in_Merged!A:C,1,0),"") -> dwelling
A15: num_sleeping_rooms | B15: =A15 -> num_sleeping_rooms | C15: num_sleeping_rooms | D15: nr_rooms | E15: =IFERROR(VLOOKUP(A15,All_Variables_in_Merged!A:C,1,0),IFERROR(VLOOKUP(B15,All_Variables_in_Merged!A:C,1,0),IFERROR(VLOOKUP(D15,All_Variables_in_Merged!A:C,1,0),""))) -> num_sleeping_rooms | F15: =IFERROR(VLOOKUP(D15,FIOA_PMT_Variables_in_Merged!A:C,1,0),"") -> nr_rooms
A16: household_own_rent_dwelling | B16: =A16 -> household_own_rent_dwelling | C16: household_own_rent_dwelling | D16: ownership_dwelling | E16: =IFERROR(VLOOKUP(A16,All_Variables_in_Merged!A:C,1,0),IFERROR(VLOOKUP(B16,All_Variables_in_Merged!A:C,1,0),IFERROR(VLOOKUP(D16,All_Variables_in_Merged!A:C,1,0),""))) -> household_own_rent_dwelling | F16: =IFERROR(VLOOKUP(D16,FIOA_PMT_Variables_in_Merged!A:C,1,0),"") -> ownership_dwelling
D17: tenure_status | E17: =IFERROR(VLOOKUP(A17,All_Variables_in_Merged!A:C,1,0),IFERROR(VLOOKUP(B17,All_Variables_in_Merged!A:C,1,0),IFERROR(VLOOKUP(D17,All_Variables_in_Merged!A:C,1,0),"")))
A18: roof_material | B18: roof_material | C18: roof_material | D18: roof_material | E18: =IFERROR(VLOOKUP(A18,All_Variables_in_Merged!A:C,1,0),IFERROR(VLOOKUP(B18,All_Variables_in_Merged!A:C,1,0),IFERROR(VLOOKUP(D18,All_Variables_in_Merged!A:C,1,0),""))) -> roof_material | F18: =IFERROR(VLOOKUP(D18,FIOA_PMT_Variables_in_Merged!A:C,1,0),"") -> roof_material
A19: predominant_wall_material | B19: =A19 -> predominant_wall_material | C19: predominant_wall_material | D19: wall_material | E19: =IFERROR(VLOOKUP(A19,All_Variables_in_Merged!A:C,1,0),IFERROR(VLOOKUP(B19,All_Variables_in_Merged!A:C,1,0),IFERROR(VLOOKUP(D19,All_Variables_in_Merged!A:C,1,0),""))) -> predominant_wall_material | F19: =IFERROR(VLOOKUP(D19,FIOA_PMT_Variables_in_Merged!A:C,1,0),"") -> wall_material
A20: floor_material | B20: =A20 -> floor_material | C20: floor_material | D20: floor_material | E20: =IFERROR(VLOOKUP(A20,All_Variables_in_Merged!A:C,1,0),IFERROR(VLOOKUP(B20,All_Variables_in_Merged!A:C,1,0),IFERROR(VLOOKUP(D20,All_Variables_in_Merged!A:C,1,0),""))) -> floor_material | F20: =IFERROR(VLOOKUP(D20,FIOA_PMT_Variables_in_Merged!A:C,1,0),"") -> floor_material
A21: main_drinking_water_source | B21: =A21 -> main_drinking_water_source | C21: main_drinking_water_source | D21: drinking_water_source | E21: =IFERROR(VLOOKUP(A21,All_Variables_in_Merged!A:C,1,0),IFERROR(VLOOKUP(B21,All_Variables_in_Merged!A:C,1,0),IFERROR(VLOOKUP(D21,All_Variables_in_Merged!A:C,1,0),""))) -> main_drinking_water_source | F21: =IFERROR(VLOOKUP(D21,FIOA_PMT_Variables_in_Merged!A:C,1,0),"") -> drinking_water_source
A22: owns_telephone_installation | D22: toilet_shared | E22: =IFERROR(VLOOKUP(A22,All_Variables_in_Merged!A:C,1,0),IFERROR(VLOOKUP(B22,All_Variables_in_Merged!A:C,1,0),IFERROR(VLOOKUP(D22,All_Variables_in_Merged!A:C,1,0),""))) -> owns_telephone_installation
A23: toilet_facility_type | B23: =A23 -> toilet_facility_type | C23: toilet_facility_type | D23: toilet_facility | E23: =IFERROR(VLOOKUP(A23,All_Variables_in_Merged!A:C,1,0),IFERROR(VLOOKUP(B23,All_Variables_in_Merged!A:C,1,0),IFERROR(VLOOKUP(D23,All_Variables_in_Merged!A:C,1,0),""))) -> toilet_facility_type | F23: =IFERROR(VLOOKUP(D23,FIOA_PMT_Variables_in_Merged!A:C,1,0),"") -> toilet_facility
A24: main_cooking_energy_source | B24: =A24 -> main_cooking_energy_source | C24: main_cooking_energy_source | D24: cooking_fuel_source | E24: =IFERROR(VLOOKUP(A24,All_Variables_in_Merged!A:C,1,0),IFERROR(VLOOKUP(B24,All_Variables_in_Merged!A:C,1,0),IFERROR(VLOOKUP(D24,All_Variables_in_Merged!A:C,1,0),""))) -> main_cooking_energy_source | F24: =IFERROR(VLOOKUP(D24,FIOA_PMT_Variables_in_Merged!A:C,1,0),"") -> cooking_fuel_source
A25: main_energy_source_lighting | B25: =A25 -> main_energy_source_lighting | C25: main_energy_source_lighting | D25: lighting_source | E25: =IFERROR(VLOOKUP(A25,All_Variables_in_Merged!A:C,1,0),IFERROR(VLOOKUP(B25,All_Variables_in_Merged!A:C,1,0),IFERROR(VLOOKUP(D25,All_Variables_in_Merged!A:C,1,0),""))) -> main_energy_source_lighting | F25: =IFERROR(VLOOKUP(D25,FIOA_PMT_Variables_in_Merged!A:C,1,0),"") -> lighting_source
D26: access_electricity | E26: =IFERROR(VLOOKUP(A26,All_Variables_in_Merged!A:C,1,0),IFERROR(VLOOKUP(B26,All_Variables_in_Merged!A:C,1,0),IFERROR(VLOOKUP(D26,All_Variables_in_Merged!A:C,1,0),""))) -> access_electricity | F26: =IFERROR(VLOOKUP(D26,FIOA_PMT_Variables_in_Merged!A:C,1,0),"") -> access_electricity
A27: Radio | B27: owns_radio | C27: owns_radio | D27: own_radio | E27: =IFERROR(VLOOKUP(A27,All_Variables_in_Merged!A:C,1,0),IFERROR(VLOOKUP(B27,All_Variables_in_Merged!A:C,1,0),IFERROR(VLOOKUP(D27,All_Variables_in_Merged!A:C,1,0),""))) -> owns_radio | F27: =IFERROR(VLOOKUP(D27,FIOA_PMT_Variables_in_Merged!A:C,1,0),"") -> own_radio
A28: Television | B28: owns_television | C28: owns_television | D28: owns_tv | E28: =IFERROR(VLOOKUP(A28,All_Variables_in_Merged!A:C,1,0),IFERROR(VLOOKUP(B28,All_Variables_in_Merged!A:C,1,0),IFERROR(VLOOKUP(D28,All_Variables_in_Merged!A:C,1,0),""))) -> owns_television | F28: =IFERROR(VLOOKUP(D28,FIOA_PMT_Variables_in_Merged!A:C,1,0),"") -> owns_tv
A29: owns_telephone_installation | B29: owns_telephone_installation | C29: owns_telephone_installation | D29: own_landline | E29: =IFERROR(VLOOKUP(A29,All_Variables_in_Merged!A:C,1,0),IFERROR(VLOOKUP(B29,All_Variables_in_Merged!A:C,1,0),IFERROR(VLOOKUP(D29,All_Variables_in_Merged!A:C,1,0),""))) -> owns_telephone_installation | F29: =IFERROR(VLOOKUP(D29,FIOA_PMT_Variables_in_Merged!A:C,1,0),"") -> own_landline
A30: Computer(Desktop) | B30: owns_computerdesktop | C30: owns_computerdesktop | D30: own_desktop | E30: =IFERROR(VLOOKUP(A30,All_Variables_in_Merged!A:C,1,0),IFERROR(VLOOKUP(B30,All_Variables_in_Merged!A:C,1,0),IFERROR(VLOOKUP(D30,All_Variables_in_Merged!A:C,1,0),""))) -> owns_computerdesktop | F30: =IFERROR(VLOOKUP(D30,FIOA_PMT_Variables_in_Merged!A:C,1,0),"") -> own_desktop
A31: Computer (Laptop) | B31: owns_computer_laptop | C31: owns_computer_laptop | D31: own_laptop | E31: =IFERROR(VLOOKUP(A31,All_Variables_in_Merged!A:C,1,0),IFERROR(VLOOKUP(B31,All_Variables_in_Merged!A:C,1,0),IFERROR(VLOOKUP(D31,All_Variables_in_Merged!A:C,1,0),""))) -> owns_computer_laptop | F31: =IFERROR(VLOOKUP(D31,FIOA_PMT_Variables_in_Merged!A:C,1,0),"") -> own_laptop
A32: Computer (Tablet) | B32: owns_computer_tablet | C32: owns_computer_tablet | D32: own_tablet | E32: =IFERROR(VLOOKUP(A32,All_Variables_in_Merged!A:C,1,0),IFERROR(VLOOKUP(B32,All_Variables_in_Merged!A:C,1,0),IFERROR(VLOOKUP(D32,All_Variables_in_Merged!A:C,1,0),""))) -> owns_computer_tablet | F32: =IFERROR(VLOOKUP(D32,FIOA_PMT_Variables_in_Merged!A:C,1,0),"") -> own_tablet
D33: productive_land | E33: =IFERROR(VLOOKUP(A33,All_Variables_in_Merged!A:C,1,0),IFERROR(VLOOKUP(B33,All_Variables_in_Merged!A:C,1,0),IFERROR(VLOOKUP(D33,All_Variables_in_Merged!A:C,1,0),"")))
A34: Refrigerator/Freezers | B34: owns_refrigerator_freezers | C34: owns_refrigerator_freezers | D34: own_fridge | E34: =IFERROR(VLOOKUP(A34,All_Variables_in_Merged!A:C,1,0),IFERROR(VLOOKUP(B34,All_Variables_in_Merged!A:C,1,0),IFERROR(VLOOKUP(D34,All_Variables_in_Merged!A:C,1,0),""))) -> owns_refrigerator_freezers | F34: =IFERROR(VLOOKUP(D34,FIOA_PMT_Variables_in_Merged!A:C,1,0),"") -> own_fridge
A35: Home theatre | B35: owns_home_theatre | C35: owns_home_theatre | D35: own_hometheatre | E35: =IFERROR(VLOOKUP(A35,All_Variables_in_Merged!A:C,1,0),IFERROR(VLOOKUP(B35,All_Variables_in_Merged!A:C,1,0),IFERROR(VLOOKUP(D35,All_Variables_in_Merged!A:C,1,0),""))) -> owns_home_theatre | F35: =IFERROR(VLOOKUP(D35,FIOA_PMT_Variables_in_Merged!A:C,1,0),"") -> own_hometheatre
A36: Mobile Handset-basic/smartphone | B36: owns_mobile_handset_basic_smartphone | C36: owns_mobile_handset_basic_smartphone | D36: own_phone | E36: =IFERROR(VLOOKUP(A36,All_Variables_in_Merged!A:C,1,0),IFERROR(VLOOKUP(B36,All_Variables_in_Merged!A:C,1,0),IFERROR(VLOOKUP(D36,All_Variables_in_Merged!A:C,1,0),""))) -> owns_mobile_handset_basic_smartphone | F36: =IFERROR(VLOOKUP(D36,FIOA_PMT_Variables_in_Merged!A:C,1,0),"") -> own_phone
A37: Motorcycle for personal use | B37: owns_motorcycle_for_personal_use | C37: owns_motorcycle_for_personal_use | D37: own_mtcycle | E37: =IFERROR(VLOOKUP(A37,All_Variables_in_Merged!A:C,1,0),IFERROR(VLOOKUP(B37,All_Variables_in_Merged!A:C,1,0),IFERROR(VLOOKUP(D37,All_Variables_in_Merged!A:C,1,0),""))) -> owns_motorcycle_for_personal_use | F37: =IFERROR(VLOOKUP(D37,FIOA_PMT_Variables_in_Merged!A:C,1,0),"") -> own_mtcycle
A38: Bicycle/Tricycles for personal use | B38: owns_bicycle_tricycles_for_personal_use | C38: owns_bicycle_tricycles_for_personal_use | D38: own_bicycle | E38: =IFERROR(VLOOKUP(A38,All_Variables_in_Merged!A:C,1,0),IFERROR(VLOOKUP(B38,All_Variables_in_Merged!A:C,1,0),IFERROR(VLOOKUP(D38,All_Variables_in_Merged!A:C,1,0),""))) -> owns_bicycle_tricycles_for_personal_use | F38: =IFERROR(VLOOKUP(D38,FIOA_PMT_Variables_in_Merged!A:C,1,0),"") -> own_bicycle
A39: Car for personal use | B39: owns_car_for_personal_use | C39: owns_car_for_personal_use | D39: own_car | E39: =IFERROR(VLOOKUP(A39,All_Variables_in_Merged!A:C,1,0),IFERROR(VLOOKUP(B39,All_Variables_in_Merged!A:C,1,0),IFERROR(VLOOKUP(D39,All_Variables_in_Merged!A:C,1,0),""))) -> owns_car_for_personal_use | F39: =IFERROR(VLOOKUP(D39,FIOA_PMT_Variables_in_Merged!A:C,1,0),"") -> own_car
A40: Pick-Up for personal use | B40: owns_pick_up_for_personal_use | C40: owns_pick_up_for_personal_use | D40: owns_pickup | E40: =IFERROR(VLOOKUP(A40,All_Variables_in_Merged!A:C,1,0),IFERROR(VLOOKUP(B40,All_Variables_in_Merged!A:C,1,0),IFERROR(VLOOKUP(D40,All_Variables_in_Merged!A:C,1,0),""))) -> owns_pick_up_for_personal_use | F40: =IFERROR(VLOOKUP(D40,FIOA_PMT_Variables_in_Merged!A:C,1,0),"") -> owns_pickup
...

Sheet ibs_2015_pmt_variables
A1: FOI | B1: Rename | C1: IBS current
A2: County | B2: County | C2: county
A3: household_size | B3: household_size | C3: total_persons_in_household
A4: hhhead_sex | B4: sex | C4: sex
A5: hhhead_working | B5: did_not_work | C5: even_though_name_did_not_do_any_of_these_activities_in_the_last_7_days_does_
A6: marital_status | B6: marital_status | C6: what_is_names_marital_status
A7: education_level | B7: education_level | C7: what_is_the_highest_educational_level_and_grade_name_has_completed
A8: dwelling | B8: dwelling | C8: what_type_of_dwelling_does_the_household_live_in
A9: nr_rooms | B9: nr_rooms | C9: how_many_habitable_rooms_does_this_hh_occupy__main_dwelling
A10: ownership_dwelling | B10: ownership_dwelling | C10: does_your_household_own_this_dwelling_house_flatshack_do_you_rent_it_or_do
A11: tenure_status | B11: tenure_status | C11: how_did_hh_acquire_this_dwelling
A12: roof_material | B12: roof_material | C12: what_is_the_predominant_roof_material_of_the_main_dwelling_unit
... A43: occupation | B43: primary_occupation_description | C43: what_kind_of_economic_activity_is_names_main_job_connected_with_i.e._typ
A44: mm_age
A45: prop_over65
A46: prop_under5
A47: prop_m1864
A48: prop_w1864
A49: unique_id

Sheet pmt_variables
A1: newFIOA_name
A2: County
A3: household_size
A4: mm_age
A5: prop_over65
A6: prop_under5
A7: prop_m1864
A8: prop_w1864
A9: hhhead_woman
A10: working
A11: marital_status
A12: education_level
... A44: land_size

Sheet All_Variables_in_Merged
A1: variable_name | B1: data_type | C1: non_null_count
A2: strid | B2: float64 | C2: 17042
A3: hhid | B3: float64 | C3: 17042
A4: respondent_id | B4: int64 | C4: 17042
A5: county | B5: object | C5: 17042
A6: urban_rural_classification | B6: object | C6: 17042
A7: stratum | B7: int64 | C7: 17042
A8: relationship_to_household_head | B8: object | C8: 17042
A9: sex | B9: object | C9: 17042
A10: age_years | B10: float64 | C10: 17036
A11: age_months | B11: float64 | C11: 0
A12: date_of_birth_year | B12: float64 | C12: 17042
A13: marital_status | B13: object | C13: 17042
... A929: access_electricity | B929: object | C929: 17042

Sheet FIOA_PMT_Variables_in_Merged
A1: variable_name | B1: data_type | C1: non_null_count
A2: hhid | B2: float64 | C2: 17042
A3: County | B3: object | C3: 17042
A4: household_size | B4: float64 | C4: 17042
A5: mm_age | B5: float64 | C5: 17042
A6: prop_over65 | B6: float64 | C6: 17042
A7: prop_under5 | B7: float64 | C7: 17042
A8: prop_m1864 | B8: float64 | C8: 17042
A9: prop_w1864 | B9: float64 | C9: 17042
A10: hhhead_woman | B10: object | C10: 17042
A11: working | B11: object | C11: 17039
A12: marital_status | B12: object | C12: 17042
A13: dwelling | B13: object | C13: 17042
... A42: padqexp | B42: float64 | C42: 16963
